2020-04-16 14:47:35,179 ERROR: Exception on /index [GET] [in /Users/nathanielgertzman/opt/anaconda3/lib/python3.7/site-packages/flask/app.py:1891]
Traceback (most recent call last):
  File "/Users/nathanielgertzman/opt/anaconda3/lib/python3.7/site-packages/flask/app.py", line 2446, in wsgi_app
    response = self.full_dispatch_request()
  File "/Users/nathanielgertzman/opt/anaconda3/lib/python3.7/site-packages/flask/app.py", line 1951, in full_dispatch_request
    rv = self.handle_user_exception(e)
  File "/Users/nathanielgertzman/opt/anaconda3/lib/python3.7/site-packages/flask/app.py", line 1820, in handle_user_exception
    reraise(exc_type, exc_value, tb)
  File "/Users/nathanielgertzman/opt/anaconda3/lib/python3.7/site-packages/flask/_compat.py", line 39, in reraise
    raise value
  File "/Users/nathanielgertzman/opt/anaconda3/lib/python3.7/site-packages/flask/app.py", line 1949, in full_dispatch_request
    rv = self.dispatch_request()
  File "/Users/nathanielgertzman/opt/anaconda3/lib/python3.7/site-packages/flask/app.py", line 1935, in dispatch_request
    return self.view_functions[rule.endpoint](**req.view_args)
  File "/Users/nathanielgertzman/opt/anaconda3/lib/python3.7/site-packages/flask_login/utils.py", line 272, in decorated_view
    return func(*args, **kwargs)
  File "/Users/nathanielgertzman/Documents/Python/Flask/microblog/app/routes.py", line 28, in index
    posts = posts.items, next_url = next_url, prev_url = prev_url)
  File "/Users/nathanielgertzman/opt/anaconda3/lib/python3.7/site-packages/flask/templating.py", line 138, in render_template
    ctx.app.jinja_env.get_or_select_template(template_name_or_list),
  File "/Users/nathanielgertzman/opt/anaconda3/lib/python3.7/site-packages/jinja2/environment.py", line 930, in get_or_select_template
    return self.get_template(template_name_or_list, parent, globals)
  File "/Users/nathanielgertzman/opt/anaconda3/lib/python3.7/site-packages/jinja2/environment.py", line 883, in get_template
    return self._load_template(name, self.make_globals(globals))
  File "/Users/nathanielgertzman/opt/anaconda3/lib/python3.7/site-packages/jinja2/environment.py", line 857, in _load_template
    template = self.loader.load(self, name, globals)
  File "/Users/nathanielgertzman/opt/anaconda3/lib/python3.7/site-packages/jinja2/loaders.py", line 129, in load
    code = environment.compile(source, name, filename)
  File "/Users/nathanielgertzman/opt/anaconda3/lib/python3.7/site-packages/jinja2/environment.py", line 638, in compile
    self.handle_exception(source=source_hint)
  File "/Users/nathanielgertzman/opt/anaconda3/lib/python3.7/site-packages/jinja2/environment.py", line 832, in handle_exception
    reraise(*rewrite_traceback_stack(source=source))
  File "/Users/nathanielgertzman/opt/anaconda3/lib/python3.7/site-packages/jinja2/_compat.py", line 28, in reraise
    raise value.with_traceback(tb)
  File "/Users/nathanielgertzman/Documents/Python/Flask/microblog/app/templates/index.html", line 26, in template
    <a href="{{ next_url }">Older posts</a>
jinja2.exceptions.TemplateSyntaxError: unexpected '}'
2020-04-16 14:47:51,507 INFO: Microblog startup [in /Users/nathanielgertzman/Documents/Python/Flask/microblog/app/__init__.py:45]
2020-04-16 15:04:22,908 INFO: Microblog startup [in /Users/nathanielgertzman/Documents/Python/Flask/microblog/app/__init__.py:45]
2020-04-16 15:04:50,260 INFO: Microblog startup [in /Users/nathanielgertzman/Documents/Python/Flask/microblog/app/__init__.py:45]
2020-04-16 16:36:44,894 INFO: Microblog startup [in /Users/nathanielgertzman/Documents/Python/Flask/microblog/app/__init__.py:45]
2020-04-17 14:22:48,766 INFO: Microblog startup [in /Users/nathanielgertzman/Documents/Python/Flask/microblog/app/__init__.py:47]
2020-04-17 14:29:14,158 INFO: Microblog startup [in /Users/nathanielgertzman/Documents/Python/Flask/microblog/app/__init__.py:47]
2020-04-20 01:44:33,073 INFO: Microblog startup [in /Users/nathanielgertzman/Documents/Python/Flask/microblog/app/__init__.py:47]
2020-04-20 01:45:32,332 ERROR: Exception on /reset_password_request [POST] [in /Users/nathanielgertzman/opt/anaconda3/lib/python3.7/site-packages/flask/app.py:1891]
Traceback (most recent call last):
  File "/Users/nathanielgertzman/opt/anaconda3/lib/python3.7/site-packages/flask/app.py", line 2446, in wsgi_app
    response = self.full_dispatch_request()
  File "/Users/nathanielgertzman/opt/anaconda3/lib/python3.7/site-packages/flask/app.py", line 1951, in full_dispatch_request
    rv = self.handle_user_exception(e)
  File "/Users/nathanielgertzman/opt/anaconda3/lib/python3.7/site-packages/flask/app.py", line 1820, in handle_user_exception
    reraise(exc_type, exc_value, tb)
  File "/Users/nathanielgertzman/opt/anaconda3/lib/python3.7/site-packages/flask/_compat.py", line 39, in reraise
    raise value
  File "/Users/nathanielgertzman/opt/anaconda3/lib/python3.7/site-packages/flask/app.py", line 1949, in full_dispatch_request
    rv = self.dispatch_request()
  File "/Users/nathanielgertzman/opt/anaconda3/lib/python3.7/site-packages/flask/app.py", line 1935, in dispatch_request
    return self.view_functions[rule.endpoint](**req.view_args)
  File "/Users/nathanielgertzman/Documents/Python/Flask/microblog/app/routes.py", line 154, in reset_password_request
    send_password_reset_email(user)
  File "/Users/nathanielgertzman/Documents/Python/Flask/microblog/app/email.py", line 12, in send_password_reset_email
    token = user.get_reset_password_token()
  File "/Users/nathanielgertzman/Documents/Python/Flask/microblog/app/models.py", line 67, in get_reset_password_token
    {'reset_password': self.id, 'exp': time() + expires_in},
NameError: name 'self' is not defined
2020-04-20 01:46:41,853 INFO: Microblog startup [in /Users/nathanielgertzman/Documents/Python/Flask/microblog/app/__init__.py:47]
2020-04-20 01:46:49,685 ERROR: Exception on /reset_password_request [POST] [in /Users/nathanielgertzman/opt/anaconda3/lib/python3.7/site-packages/flask/app.py:1891]
Traceback (most recent call last):
  File "/Users/nathanielgertzman/opt/anaconda3/lib/python3.7/site-packages/flask/app.py", line 2446, in wsgi_app
    response = self.full_dispatch_request()
  File "/Users/nathanielgertzman/opt/anaconda3/lib/python3.7/site-packages/flask/app.py", line 1951, in full_dispatch_request
    rv = self.handle_user_exception(e)
  File "/Users/nathanielgertzman/opt/anaconda3/lib/python3.7/site-packages/flask/app.py", line 1820, in handle_user_exception
    reraise(exc_type, exc_value, tb)
  File "/Users/nathanielgertzman/opt/anaconda3/lib/python3.7/site-packages/flask/_compat.py", line 39, in reraise
    raise value
  File "/Users/nathanielgertzman/opt/anaconda3/lib/python3.7/site-packages/flask/app.py", line 1949, in full_dispatch_request
    rv = self.dispatch_request()
  File "/Users/nathanielgertzman/opt/anaconda3/lib/python3.7/site-packages/flask/app.py", line 1935, in dispatch_request
    return self.view_functions[rule.endpoint](**req.view_args)
  File "/Users/nathanielgertzman/Documents/Python/Flask/microblog/app/routes.py", line 154, in reset_password_request
    send_password_reset_email(user)
  File "/Users/nathanielgertzman/Documents/Python/Flask/microblog/app/email.py", line 19, in send_password_reset_email
    user = user, token = token))
  File "/Users/nathanielgertzman/opt/anaconda3/lib/python3.7/site-packages/flask/templating.py", line 138, in render_template
    ctx.app.jinja_env.get_or_select_template(template_name_or_list),
  File "/Users/nathanielgertzman/opt/anaconda3/lib/python3.7/site-packages/jinja2/environment.py", line 930, in get_or_select_template
    return self.get_template(template_name_or_list, parent, globals)
  File "/Users/nathanielgertzman/opt/anaconda3/lib/python3.7/site-packages/jinja2/environment.py", line 883, in get_template
    return self._load_template(name, self.make_globals(globals))
  File "/Users/nathanielgertzman/opt/anaconda3/lib/python3.7/site-packages/jinja2/environment.py", line 857, in _load_template
    template = self.loader.load(self, name, globals)
  File "/Users/nathanielgertzman/opt/anaconda3/lib/python3.7/site-packages/jinja2/loaders.py", line 129, in load
    code = environment.compile(source, name, filename)
  File "/Users/nathanielgertzman/opt/anaconda3/lib/python3.7/site-packages/jinja2/environment.py", line 638, in compile
    self.handle_exception(source=source_hint)
  File "/Users/nathanielgertzman/opt/anaconda3/lib/python3.7/site-packages/jinja2/environment.py", line 832, in handle_exception
    reraise(*rewrite_traceback_stack(source=source))
  File "/Users/nathanielgertzman/opt/anaconda3/lib/python3.7/site-packages/jinja2/_compat.py", line 28, in reraise
    raise value.with_traceback(tb)
  File "/Users/nathanielgertzman/Documents/Python/Flask/microblog/app/templates/email/reset_password.html", line 9, in template
    <p>{{ url_for('reset_password', token = token, _external = True</p>
jinja2.exceptions.TemplateSyntaxError: unexpected '/'
2020-04-20 01:47:56,433 INFO: Microblog startup [in /Users/nathanielgertzman/Documents/Python/Flask/microblog/app/__init__.py:47]
