2020-04-29 13:59:39,833 ERROR: Exception on /index [POST] [in /Users/nathanielgertzman/opt/anaconda3/lib/python3.7/site-packages/flask/app.py:1891]
Traceback (most recent call last):
  File "/Users/nathanielgertzman/opt/anaconda3/lib/python3.7/site-packages/urllib3/connection.py", line 157, in _new_conn
    (self._dns_host, self.port), self.timeout, **extra_kw
  File "/Users/nathanielgertzman/opt/anaconda3/lib/python3.7/site-packages/urllib3/util/connection.py", line 84, in create_connection
    raise err
  File "/Users/nathanielgertzman/opt/anaconda3/lib/python3.7/site-packages/urllib3/util/connection.py", line 74, in create_connection
    sock.connect(sa)
ConnectionRefusedError: [Errno 61] Connection refused

During handling of the above exception, another exception occurred:

Traceback (most recent call last):
  File "/Users/nathanielgertzman/opt/anaconda3/lib/python3.7/site-packages/elasticsearch/connection/http_urllib3.py", line 229, in perform_request
    method, url, body, retries=Retry(False), headers=request_headers, **kw
  File "/Users/nathanielgertzman/opt/anaconda3/lib/python3.7/site-packages/urllib3/connectionpool.py", line 720, in urlopen
    method, url, error=e, _pool=self, _stacktrace=sys.exc_info()[2]
  File "/Users/nathanielgertzman/opt/anaconda3/lib/python3.7/site-packages/urllib3/util/retry.py", line 376, in increment
    raise six.reraise(type(error), error, _stacktrace)
  File "/Users/nathanielgertzman/opt/anaconda3/lib/python3.7/site-packages/urllib3/packages/six.py", line 735, in reraise
    raise value
  File "/Users/nathanielgertzman/opt/anaconda3/lib/python3.7/site-packages/urllib3/connectionpool.py", line 672, in urlopen
    chunked=chunked,
  File "/Users/nathanielgertzman/opt/anaconda3/lib/python3.7/site-packages/urllib3/connectionpool.py", line 387, in _make_request
    conn.request(method, url, **httplib_request_kw)
  File "/Users/nathanielgertzman/opt/anaconda3/lib/python3.7/http/client.py", line 1252, in request
    self._send_request(method, url, body, headers, encode_chunked)
  File "/Users/nathanielgertzman/opt/anaconda3/lib/python3.7/http/client.py", line 1298, in _send_request
    self.endheaders(body, encode_chunked=encode_chunked)
  File "/Users/nathanielgertzman/opt/anaconda3/lib/python3.7/http/client.py", line 1247, in endheaders
    self._send_output(message_body, encode_chunked=encode_chunked)
  File "/Users/nathanielgertzman/opt/anaconda3/lib/python3.7/http/client.py", line 1026, in _send_output
    self.send(msg)
  File "/Users/nathanielgertzman/opt/anaconda3/lib/python3.7/http/client.py", line 966, in send
    self.connect()
  File "/Users/nathanielgertzman/opt/anaconda3/lib/python3.7/site-packages/urllib3/connection.py", line 184, in connect
    conn = self._new_conn()
  File "/Users/nathanielgertzman/opt/anaconda3/lib/python3.7/site-packages/urllib3/connection.py", line 169, in _new_conn
    self, "Failed to establish a new connection: %s" % e
urllib3.exceptions.NewConnectionError: <urllib3.connection.HTTPConnection object at 0x1039a6a50>: Failed to establish a new connection: [Errno 61] Connection refused

During handling of the above exception, another exception occurred:

Traceback (most recent call last):
  File "/Users/nathanielgertzman/opt/anaconda3/lib/python3.7/site-packages/flask/app.py", line 2446, in wsgi_app
    response = self.full_dispatch_request()
  File "/Users/nathanielgertzman/opt/anaconda3/lib/python3.7/site-packages/flask/app.py", line 1951, in full_dispatch_request
    rv = self.handle_user_exception(e)
  File "/Users/nathanielgertzman/opt/anaconda3/lib/python3.7/site-packages/flask/app.py", line 1820, in handle_user_exception
    reraise(exc_type, exc_value, tb)
  File "/Users/nathanielgertzman/opt/anaconda3/lib/python3.7/site-packages/flask/_compat.py", line 39, in reraise
    raise value
  File "/Users/nathanielgertzman/opt/anaconda3/lib/python3.7/site-packages/flask/app.py", line 1949, in full_dispatch_request
    rv = self.dispatch_request()
  File "/Users/nathanielgertzman/opt/anaconda3/lib/python3.7/site-packages/flask/app.py", line 1935, in dispatch_request
    return self.view_functions[rule.endpoint](**req.view_args)
  File "/Users/nathanielgertzman/opt/anaconda3/lib/python3.7/site-packages/flask_login/utils.py", line 272, in decorated_view
    return func(*args, **kwargs)
  File "/Users/nathanielgertzman/Documents/Python/Flask/microblog/app/routes.py", line 26, in index
    db.session.commit()
  File "/Users/nathanielgertzman/opt/anaconda3/lib/python3.7/site-packages/sqlalchemy/orm/scoping.py", line 162, in do
    return getattr(self.registry(), name)(*args, **kwargs)
  File "/Users/nathanielgertzman/opt/anaconda3/lib/python3.7/site-packages/sqlalchemy/orm/session.py", line 1036, in commit
    self.transaction.commit()
  File "/Users/nathanielgertzman/opt/anaconda3/lib/python3.7/site-packages/sqlalchemy/orm/session.py", line 510, in commit
    self.session.dispatch.after_commit(self.session)
  File "/Users/nathanielgertzman/opt/anaconda3/lib/python3.7/site-packages/sqlalchemy/event/attr.py", line 261, in __call__
    fn(*args, **kw)
  File "/Users/nathanielgertzman/Documents/Python/Flask/microblog/app/models.py", line 108, in after_commit
    add_to_index(obj.__tablename__, obj)
  File "/Users/nathanielgertzman/Documents/Python/Flask/microblog/app/search.py", line 9, in add_to_index
    current_app.elasticsearch.index(index = index, id = model.id, body = payload)
  File "/Users/nathanielgertzman/opt/anaconda3/lib/python3.7/site-packages/elasticsearch/client/utils.py", line 92, in _wrapped
    return func(*args, params=params, headers=headers, **kwargs)
  File "/Users/nathanielgertzman/opt/anaconda3/lib/python3.7/site-packages/elasticsearch/client/__init__.py", line 407, in index
    body=body,
  File "/Users/nathanielgertzman/opt/anaconda3/lib/python3.7/site-packages/elasticsearch/transport.py", line 362, in perform_request
    timeout=timeout,
  File "/Users/nathanielgertzman/opt/anaconda3/lib/python3.7/site-packages/elasticsearch/connection/http_urllib3.py", line 241, in perform_request
    raise ConnectionError("N/A", str(e), e)
elasticsearch.exceptions.ConnectionError: ConnectionError(<urllib3.connection.HTTPConnection object at 0x1039a6a50>: Failed to establish a new connection: [Errno 61] Connection refused) caused by: NewConnectionError(<urllib3.connection.HTTPConnection object at 0x1039a6a50>: Failed to establish a new connection: [Errno 61] Connection refused)
