2020-04-27 02:19:27,480 ERROR: Exception on /search [GET] [in /Users/nathanielgertzman/opt/anaconda3/lib/python3.7/site-packages/flask/app.py:1891]
Traceback (most recent call last):
  File "/Users/nathanielgertzman/opt/anaconda3/lib/python3.7/site-packages/flask/app.py", line 2446, in wsgi_app
    response = self.full_dispatch_request()
  File "/Users/nathanielgertzman/opt/anaconda3/lib/python3.7/site-packages/flask/app.py", line 1951, in full_dispatch_request
    rv = self.handle_user_exception(e)
  File "/Users/nathanielgertzman/opt/anaconda3/lib/python3.7/site-packages/flask/app.py", line 1820, in handle_user_exception
    reraise(exc_type, exc_value, tb)
  File "/Users/nathanielgertzman/opt/anaconda3/lib/python3.7/site-packages/flask/_compat.py", line 39, in reraise
    raise value
  File "/Users/nathanielgertzman/opt/anaconda3/lib/python3.7/site-packages/flask/app.py", line 1949, in full_dispatch_request
    rv = self.dispatch_request()
  File "/Users/nathanielgertzman/opt/anaconda3/lib/python3.7/site-packages/flask/app.py", line 1935, in dispatch_request
    return self.view_functions[rule.endpoint](**req.view_args)
  File "/Users/nathanielgertzman/opt/anaconda3/lib/python3.7/site-packages/flask_login/utils.py", line 272, in decorated_view
    return func(*args, **kwargs)
  File "/Users/nathanielgertzman/Documents/Python/Flask/microblog/app/routes.py", line 232, in search
    posts, total = Post.search(g.search_form.q.data, page,
AttributeError: type object 'Post' has no attribute 'search'
2020-04-27 02:20:36,505 INFO: Microblog startup [in /Users/nathanielgertzman/Documents/Python/Flask/microblog/app/__init__.py:54]
2020-04-27 02:20:42,129 INFO: Microblog startup [in /Users/nathanielgertzman/Documents/Python/Flask/microblog/app/__init__.py:54]
2020-04-27 02:20:48,483 INFO: Microblog startup [in /Users/nathanielgertzman/Documents/Python/Flask/microblog/app/__init__.py:54]
2020-04-27 02:20:57,149 ERROR: Exception on /search [GET] [in /Users/nathanielgertzman/opt/anaconda3/lib/python3.7/site-packages/flask/app.py:1891]
Traceback (most recent call last):
  File "/Users/nathanielgertzman/opt/anaconda3/lib/python3.7/site-packages/flask/app.py", line 2446, in wsgi_app
    response = self.full_dispatch_request()
  File "/Users/nathanielgertzman/opt/anaconda3/lib/python3.7/site-packages/flask/app.py", line 1951, in full_dispatch_request
    rv = self.handle_user_exception(e)
  File "/Users/nathanielgertzman/opt/anaconda3/lib/python3.7/site-packages/flask/app.py", line 1820, in handle_user_exception
    reraise(exc_type, exc_value, tb)
  File "/Users/nathanielgertzman/opt/anaconda3/lib/python3.7/site-packages/flask/_compat.py", line 39, in reraise
    raise value
  File "/Users/nathanielgertzman/opt/anaconda3/lib/python3.7/site-packages/flask/app.py", line 1949, in full_dispatch_request
    rv = self.dispatch_request()
  File "/Users/nathanielgertzman/opt/anaconda3/lib/python3.7/site-packages/flask/app.py", line 1935, in dispatch_request
    return self.view_functions[rule.endpoint](**req.view_args)
  File "/Users/nathanielgertzman/opt/anaconda3/lib/python3.7/site-packages/flask_login/utils.py", line 272, in decorated_view
    return func(*args, **kwargs)
  File "/Users/nathanielgertzman/Documents/Python/Flask/microblog/app/routes.py", line 232, in search
    posts, total = Post.search(g.search_form.q.data, page,
AttributeError: type object 'Post' has no attribute 'search'
2020-04-27 02:22:20,821 INFO: Microblog startup [in /Users/nathanielgertzman/Documents/Python/Flask/microblog/app/__init__.py:54]
2020-04-27 02:23:03,928 INFO: Microblog startup [in /Users/nathanielgertzman/Documents/Python/Flask/microblog/app/__init__.py:54]
2020-04-27 02:23:09,406 ERROR: Exception on /search [GET] [in /Users/nathanielgertzman/opt/anaconda3/lib/python3.7/site-packages/flask/app.py:1891]
Traceback (most recent call last):
  File "/Users/nathanielgertzman/opt/anaconda3/lib/python3.7/site-packages/flask/app.py", line 2446, in wsgi_app
    response = self.full_dispatch_request()
  File "/Users/nathanielgertzman/opt/anaconda3/lib/python3.7/site-packages/flask/app.py", line 1951, in full_dispatch_request
    rv = self.handle_user_exception(e)
  File "/Users/nathanielgertzman/opt/anaconda3/lib/python3.7/site-packages/flask/app.py", line 1820, in handle_user_exception
    reraise(exc_type, exc_value, tb)
  File "/Users/nathanielgertzman/opt/anaconda3/lib/python3.7/site-packages/flask/_compat.py", line 39, in reraise
    raise value
  File "/Users/nathanielgertzman/opt/anaconda3/lib/python3.7/site-packages/flask/app.py", line 1949, in full_dispatch_request
    rv = self.dispatch_request()
  File "/Users/nathanielgertzman/opt/anaconda3/lib/python3.7/site-packages/flask/app.py", line 1935, in dispatch_request
    return self.view_functions[rule.endpoint](**req.view_args)
  File "/Users/nathanielgertzman/opt/anaconda3/lib/python3.7/site-packages/flask_login/utils.py", line 272, in decorated_view
    return func(*args, **kwargs)
  File "/Users/nathanielgertzman/Documents/Python/Flask/microblog/app/routes.py", line 233, in search
    current_app.config['POSTS_PER_PAGE'])
NameError: name 'current_app' is not defined
2020-04-27 02:23:22,535 INFO: Microblog startup [in /Users/nathanielgertzman/Documents/Python/Flask/microblog/app/__init__.py:54]
2020-04-27 02:24:28,950 INFO: Microblog startup [in /Users/nathanielgertzman/Documents/Python/Flask/microblog/app/__init__.py:54]
2020-04-27 03:23:22,358 INFO: Microblog startup [in /Users/nathanielgertzman/Documents/Python/Flask/microblog/app/__init__.py:54]
